Workbook

Sheet Customer Names
A1: Customer ID | B1: Title Name | C1: First Name | D1: Last Name
A2: Id1 | B2: Ms | C2: Kelly | D2: Hawks
A3: Id2 | B3: Mr | C3: Matthew D | D3: Lehner
A4: Id3 | B4: Mr | C4: Phil | D4: Lu
A5: Id4 | B5: Ms | C5: Kelsey | D5: Osborne
A6: Id5 | B6: Ms | C6: Kristyn | D6: Kadala
A7: Id6 | B7: Mr | C7: Russell B | D7: Baker
A8: Id7 | B8: Mr | C8: Scott | D8: Macpherson
A9: Id8 | B9: Mr | C9: Stephen | D9: Hallman
A10: Id9 | B10: Mr | C10: Patrick R | D10: Moran
A11: Id10 | B11: Ms | C11: Brooke N | D11: Benner
A12: Id11 | B12: Ms | C12: Paola Andrea | D12: Fierro Vargas
... A2336: Id2335 | B2336: Mr | C2336: Aaron K | D2336: German

Sheet Medical Examinations
A1: Customer ID | B1: BMI | C1: Weight Status | D1: HBA1C | E1: Heart Issues | F1: Any Transplants | G1: Cancer history | H1: NumberOfMajorSurgeries | I1: smoker | K1: No of Missing Values in Smoker
A2: Id1 | B2: 47.41 | C2: =IF(B2<18.5,"Underweight",IF(B2<=24.9,"Normal weight",IF(B2<=29.9,"Overweight","Obese"))) -> Obese | D2: 7.47 | E2: No | F2: No | G2: No | H2: 0 | I2: Yes | K2: =COUNTIF('Medical Examinations'!I2:I2336,"?") -> 0
A3: Id2 | B3: 30.36 | C3: =IF(B3<18.5,"Underweight",IF(B3<=24.9,"Normal weight",IF(B3<=29.9,"Overweight","Obese"))) -> Obese | D3: 5.77 | E3: No | F3: No | G3: No | H3: 0 | I3: Yes
A4: Id3 | B4: 34.485 | C4: =IF(B4<18.5,"Underweight",IF(B4<=24.9,"Normal weight",IF(B4<=29.9,"Overweight","Obese"))) -> Obese | D4: 11.87 | E4: No | F4: No | G4: No | H4: 2 | I4: Yes | K4: =COUNTIF(A2:A2344," ") -> 0
A5: Id4 | B5: 38.095 | C5: =IF(B5<18.5,"Underweight",IF(B5<=24.9,"Normal weight",IF(B5<=29.9,"Overweight","Obese"))) -> Obese | D5: 6.05 | E5: No | F5: No | G5: No | H5: 0 | I5: Yes
A6: Id5 | B6: 35.53 | C6: =IF(B6<18.5,"Underweight",IF(B6<=24.9,"Normal weight",IF(B6<=29.9,"Overweight","Obese"))) -> Obese | D6: 5.45 | E6: No | F6: No | G6: No | H6: 0 | I6: Yes
A7: Id6 | B7: 32.8 | C7: =IF(B7<18.5,"Underweight",IF(B7<=24.9,"Normal weight",IF(B7<=29.9,"Overweight","Obese"))) -> Obese | D7: 6.59 | E7: No | F7: No | G7: No | H7: 0 | I7: Yes
A8: Id7 | B8: 36.4 | C8: =IF(B8<18.5,"Underweight",IF(B8<=24.9,"Normal weight",IF(B8<=29.9,"Overweight","Obese"))) -> Obese | D8: 6.07 | E8: No | F8: No | G8: No | H8: 0 | I8: Yes
A9: Id8 | B9: 36.96 | C9: =IF(B9<18.5,"Underweight",IF(B9<=24.9,"Normal weight",IF(B9<=29.9,"Overweight","Obese"))) -> Obese | D9: 7.93 | E9: No | F9: No | G9: No | H9: 3 | I9: Yes
A10: Id9 | B10: 41.14 | C10: =IF(B10<18.5,"Underweight",IF(B10<=24.9,"Normal weight",IF(B10<=29.9,"Overweight","Obese"))) -> Obese | D10: 9.58 | E10: No | F10: No | G10: Yes | H10: 1 | I10: Yes
A11: Id10 | B11: 38.06 | C11: =IF(B11<18.5,"Underweight",IF(B11<=24.9,"Normal weight",IF(B11<=29.9,"Overweight","Obese"))) -> Obese | D11: 10.79 | E11: No | F11: No | G11: No | H11: 0 | I11: Yes
A12: Id11 | B12: 37.7 | C12: =IF(B12<18.5,"Underweight",IF(B12<=24.9,"Normal weight",IF(B12<=29.9,"Overweight","Obese"))) -> Obese | D12: 5.96 | E12: No | F12: No | G12: No | H12: 2 | I12: Yes
A13: Id12 | B13: 42.13 | C13: =IF(B13<18.5,"Underweight",IF(B13<=24.9,"Normal weight",IF(B13<=29.9,"Overweight","Obese"))) -> Obese | D13: 11.9 | E13: No | F13: No | G13: No | H13: 0 | I13: Yes
A14: Id13 | B14: 40.92 | C14: =IF(B14<18.5,"Underweight",IF(B14<=24.9,"Normal weight",IF(B14<=29.9,"Overweight","Obese"))) -> Obese | D14: 8.41 | E14: No | F14: No | G14: No | H14: 0 | I14: Yes
A15: Id14 | B15: 40.565 | C15: =IF(B15<18.5,"Underweight",IF(B15<=24.9,"Normal weight",IF(B15<=29.9,"Overweight","Obese"))) -> Obese | D15: 7.02 | E15: No | F15: No | G15: No | H15: 0 | I15: Yes
A16: Id15 | B16: 36.385 | C16: =IF(B16<18.5,"Underweight",IF(B16<=24.9,"Normal weight",IF(B16<=29.9,"Overweight","Obese"))) -> Obese | D16: 7.59 | E16: No | F16: No | G16: No | H16: 2 | I16: Yes
... A2332: Id2331 | B2332: 22.34 | C2332: =IF(B2332<18.5,"Underweight",IF(B2332<=24.9,"Normal weight",IF(B2332<=29.9,"Overweight","Obese"))) -> Normal weight | D2332: 5.57 | E2332: No | F2332: No | G2332: No | H2332: 1 | I2332: No
A2333: Id2332 | B2333: 17.7 | D2333: 6.28 | E2333: No | F2333: No | G2333: No | H2333: 1 | I2333: No
A2334: Id2333 | B2334: 16.47 | D2334: 6.35 | E2334: No | F2334: No | G2334: Yes | H2334: 1 | I2334: No
A2335: Id2334 | B2335: 17.6 | D2335: 4.39 | E2335: No | F2335: No | G2335: No | H2335: 1 | I2335: No
A2336: Id2335 | B2336: 17.58 | D2336: 4.51 | E2336: No | F2336: No | G2336: No | H2336: 1 | I2336: No
E2337: No
E2338: No
E2339: No
E2340: No
E2341: No
E2342: No
E2343: No
E2344: No

Sheet Hospitalisation Details
A1: Customer ID | B1: year | C1: month | D1: date | E1: DOB | F1: AGE | G1: Collected data set on | H1: children | I1: Charges Changed by Currency $ | J1: hospital tier | K1: City tier | L1: State ID | N1: No Of Missing Values in Hospital
A2: Id2335 | B2: 1992 | C2: Jul | D2: 9 | E2: 9-Jul-1992 | F2: 30 | G2: 45085 | H2: 0 | I2: 563.84 | J2: tier - 2 | K2: tier - 3 | L2: R1013 | N2: =COUNTIF(A2:L2344,"?") -> 8 | Q2: tier - 2 | R2: =COUNTIF(J:J,Q2) -> 1340
A3: Id2334 | B3: 1992 | C3: Nov | D3: 30 | E3: 30-Nov-1992 | F3: 30 | G3: 45085 | H3: 0 | I3: 570.62 | J3: tier - 2 | K3: tier - 1 | L3: R1013 | Q3: tier - 3 | R3: =COUNTIF(J:J,Q3) -> 694
A4: Id2333 | B4: 1993 | C4: Jun | D4: 30 | E4: 30-Jun-1993 | F4: 29 | G4: 45085 | H4: 0 | I4: 600 | J4: tier - 2 | K4: tier - 1 | L4: R1013 | Q4: ? | R4: =COUNTIF(J:J,Q4) -> 0
A5: Id2332 | B5: 1992 | C5: Sep | D5: 13 | E5: 13-Sep-1992 | F5: 30 | G5: 45085 | H5: 0 | I5: 604.54 | J5: tier - 3 | K5: tier - 3 | L5: R1013 | Q5: tier - 1 | R5: =COUNTIF(J:J,Q5) -> 309
A6: Id2331 | B6: 1998 | C6: Jul | D6: 27 | E6: 27-Jul-1998 | F6: 24 | G6: 45085 | H6: 0 | I6: 637.26 | J6: tier - 3 | K6: tier - 3 | L6: R1013
A7: Id2330 | B7: 2001 | C7: Nov | D7: 20 | E7: 20-Nov-2001 | F7: 21 | G7: 45085 | H7: 0 | I7: 646.14 | J7: tier - 3 | K7: tier - 3 | L7: R1012
A8: Id2329 | B8: 1993 | C8: Jun | D8: 1 | E8: 1-Jun-1993 | F8: 30 | G8: 45085 | H8: 0 | I8: 650 | J8: tier - 3 | K8: tier - 3 | L8: R1013
A9: Id2328 | B9: 1995 | C9: Jul | D9: 4 | E9: 4-Jul-1995 | F9: 27 | G9: 45085 | H9: 0 | I9: 650 | J9: tier - 3 | K9: tier - 3 | L9: R1013
A10: Id2327 | B10: 2002 | C10: Nov | D10: 29 | E10: 29-Nov-2002 | F10: 20 | G10: 45085 | H10: 0 | I10: 668 | J10: tier - 3 | K10: tier - 2 | L10: R1012
A11: Id2326 | B11: 1997 | C11: Nov | D11: 9 | E11: 9-Nov-1997 | F11: 25 | G11: 45085 | H11: 0 | I11: 670 | J11: tier - 3 | K11: tier - 3 | L11: R1013
A12: Id2325 | B12: 2001 | C12: Sep | D12: 12 | E12: 12-Sep-2001 | F12: 21 | G12: 45085 | H12: 0 | I12: 687.54 | J12: tier - 3 | K12: tier - 2 | L12: R1013
A13: Id2324 | B13: 1999 | C13: Dec | D13: 26 | E13: 26-Dec-1999 | F13: 23 | G13: 45085 | H13: 0 | I13: 700 | J13: tier - 2 | K13: tier - 3 | L13: R1013
A14: Id2323 | B14: 1999 | C14: Dec | D14: 14 | E14: 14-Dec-1999 | F14: 23 | G14: 45085 | H14: 0 | I14: 722.99 | J14: tier - 3 | K14: tier - 1 | L14: R1013
A15: Id2322 | B15: 2002 | C15: Sep | D15: 19 | E15: 19-Sep-2002 | F15: 20 | G15: 45085 | H15: 0 | I15: 750 | J15: tier - 3 | K15: tier - 1 | L15: R1012
A16: Id2321 | B16: 1993 | C16: Aug | D16: 9 | E16: 9-Aug-1993 | F16: 29 | G16: 45085 | H16: 0 | I16: 760 | J16: tier - 3 | K16: tier - 1 | L16: R1013
A17: Id2320 | B17: 1996 | C17: Oct | D17: 22 | E17: 22-Oct-1996 | F17: 26 | G17: 45085 | H17: 0 | I17: 760 | J17: tier - 3 | K17: tier - 3 | L17: R1013
... A1050: Id1290 | B1050: 1977 | C1050: Jul | D1050: 26 | E1050: 26-Jul-1977 | F1050: 45 | G1050: 45085 | H1050: 2 | I1050: 8527.53 | J1050: tier - 2 | K1050: tier - 2 | L1050: R1013
A1051: Id1289 | B1051: ? | C1051: Jul | D1051: 24 | E1051: 24-Jul-? | F1051: #VALUE! | G1051: 45085 | H1051: 0 | I1051: 8534.67 | J1051: tier - 2 | K1051: tier - 3 | L1051: R1024
A1052: Id1288 | B1052: 1981 | C1052: Dec | D1052: 27 | E1052: 27-Dec-1981 | F1052: 41 | G1052: 45085 | H1052: 3 | I1052: 8538.29 | J1052: tier - 2 | K1052: tier - 3 | L1052: R1024
A1053: Id1287 | B1053: 1975 | C1053: Nov | D1053: 6 | E1053: 6-Nov-1975 | F1053: 47 | G1053: 45085 | H1053: 1 | I1053: 8539.67 | J1053: tier - 2 | K1053: tier - 3 | L1053: R1011
A1054: Id1286 | B1054: ? | C1054: Dec | D1054: 12 | E1054: 12-Dec-? | F1054: #VALUE! | G1054: 45085 | H1054: 1 | I1054: 8547.69 | J1054: tier - 2 | K1054: tier - 1 | L1054: R1013
A1055: Id1285 | B1055: 1975 | C1055: Aug | D1055: 6 | E1055: 6-Aug-1975 | F1055: 47 | G1055: 45085 | H1055: 1 | I1055: 8551.35 | J1055: tier - 2 | K1055: tier - 2 | L1055: R1011
A1056: Id1284 | B1056: 1975 | C1056: Aug | D1056: 21 | E1056: 21-Aug-1975 | F1056: 47 | G1056: 45085 | H1056: 1 | I1056: 8556.91 | J1056: tier - 2 | K1056: tier - 1 | L1056: R1011
A1057: Id1283 | B1057: 1988 | C1057: Sep | D1057: 21 | E1057: 21-Sep-1988 | F1057: 34 | G1057: 45085 | H1057: 3 | I1057: 8567.25 | J1057: tier - 2 | K1057: tier - 1 | L1057: R1012
A1058: Id1282 | B1058: 1975 | C1058: Sep | D1058: 26 | E1058: 26-Sep-1975 | F1058: 47 | G1058: 45085 | H1058: 1 | I1058: 8569.86 | J1058: tier - 2 | K1058: tier - 3 | L1058: R1013
A1059: Id1281 | B1059: 1982 | C1059: Dec | D1059: 6 | E1059: 6-Dec-1982 | F1059: 40 | G1059: 45085 | H1059: 3 | I1059: 8572.04 | J1059: tier - 2 | K1059: tier - 2 | L1059: R1021
A1060: Id1280 | B1060: 1987 | C1060: Nov | D1060: 11 | E1060: 11-Nov-1987 | F1060: 35 | G1060: 45085 | H1060: 3 | I1060: 8573.3 | J1060: tier - 2 | K1060: tier - 2 | L1060: R1021
A1061: Id1279 | B1061: 1983 | C1061: Dec | D1061: 30 | E1061: 30-Dec-1983 | F1061: 39 | G1061: 45085 | H1061: 5 | I1061: 8582.3 | J1061: tier - 2 | K1061: tier - 1 | L1061: R1013
A1062: Id1278 | B1062: 1983 | C1062: Jul | D1062: 25 | E1062: 25-Jul-1983 | F1062: 39 | G1062: 45085 | H1062: 5 | I1062: 8596.83 | J1062: tier - 2 | K1062: tier - 3 | L1062: R1013
A1063: Id1277 | B1063: 1973 | C1063: Jul | D1063: 11 | E1063: 11-Jul-1973 | F1063: 49 | G1063: 45085 | H1063: 0 | I1063: 8601.33 | J1063: tier - 2 | K1063: tier - 1 | L1063: R1013
A1064: Id1276 | B1064: 1977 | C1064: Sep | D1064: 24 | E1064: 24-Sep-1977 | F1064: 45 | G1064: 45085 | H1064: 2 | I1064: 8603.82 | J1064: tier - 2 | K1064: tier - 1 | L1064: R1019
A1065: Id1275 | B1065: 1977 | C1065: Nov | D1065: 12 | E1065: 12-Nov-1977 | F1065: 45 | G1065: 45085 | H1065: 2 | I1065: 8604.48 | J1065: tier - 3 | K1065: tier - 2 | L1065: R1016
A1066: Id1274 | B1066: 1977 | C1066: Oct | D1066: 15 | E1066: 15-Oct-1977 | F1066: 45 | G1066: 45085 | H1066: 3 | I1066: 8605.36 | J1066: tier - 2 | K1066: tier - 2 | L1066: R1013
... A2344: Id1 | B2344: 1968 | C2344: Oct | D2344: 12 | E2344: 12-Oct-1968 | F2344: 54 | G2344: 45085 | H2344: 0 | I2344: 63770.43 | J2344: tier - 1 | K2344: tier - 3 | L2344: R1013

Sheet Healthcare
A1: Customer ID | B1: =_xlfn.XLOOKUP(A1,'Customer Names'!$A$1:$A$2336,'Customer Names'!$C$1:$C$2336,0) -> First Name | C1: =_xlfn.XLOOKUP(A1,'Medical Examinations'!$A$1:$A$2336,'Medical Examinations'!$B$1:$B$2336,0) -> BMI | D1: =_xlfn.XLOOKUP(A1,'Medical Examinations'!$A$1:$A$2336,'Medical Examinations'!$D$1:$D$2336,0) -> HBA1C | E1: =_xlfn.XLOOKUP(A1,'Medical Examinations'!$A$1:$A$2336,'Medical Examinations'!$E$1:$E$2336,0) -> Heart Issues | F1: =_xlfn.XLOOKUP(A1,'Medical Examinations'!$A$1:$A$2336,'Medical Examinations'!$F$1:$F$2336,0) -> Any Transplants | G1: =_xlfn.XLOOKUP(A1,'Medical Examinations'!$A$1:$A$2336,'Medical Examinations'!$G$1:$G$2336,0) -> Cancer history | H1: =_xlfn.XLOOKUP(A1,'Medical Examinations'!$A$1:$A$2336,'Medical Examinations'!$H$1:$H$2336,0) -> NumberOfMajorSurgeries | I1: =_xlfn.XLOOKUP(A1,'Medical Examinations'!$A$1:$A$2336,'Medical Examinations'!$I$1:$I$2336,0) -> smoker | J1: =_xlfn.XLOOKUP(A1,'Medical Examinations'!A1:A2344,'Medical Examinations'!C1:C2344,0) -> Weight Status | K1: =_xlfn.XLOOKUP(A1,'Medical Examinations'!$A$1:$A$2344,'Medical Examinations'!$D$1:$D$2344,0) -> HBA1C | L1: =_xlfn.XLOOKUP(A1,'Hospitalisation Details'!$A$1:$A$2344,'Hospitalisation Details'!$E$1:$E$2344,0) -> DOB | M1: =_xlfn.XLOOKUP(A1,'Hospitalisation Details'!$A$1:$A$2344,'Hospitalisation Details'!$I$1:$I$2344,0) -> Charges Changed by Currency $ | N1: =_xlfn.XLOOKUP(A1,'Hospitalisation Details'!$A$1:$A$2344,'Hospitalisation Details'!$J$1:$J$2344,0) -> hospital tier | O1: =_xlfn.XLOOKUP(A1,'Hospitalisation Details'!$A$1:$A$2344,'Hospitalisation Details'!$K$1:$K$2344,0) -> City tier | P1: =_xlfn.XLOOKUP(A1,'Hospitalisation Details'!$A$1:$A$2344,'Hospitalisation Details'!$L$1:$L$2344,0) -> State ID | Q1: =_xlfn.XLOOKUP(A1,'Hospitalisation Details'!$A$1:$A$2344,'Hospitalisation Details'!$F$1:$F$2344,0) -> AGE
A2: Id1 | B2: =_xlfn.XLOOKUP(A2,'Customer Names'!$A$1:$A$2336,'Customer Names'!$C$1:$C$2336,0) -> Kelly | C2: =_xlfn.XLOOKUP(A2,'Medical Examinations'!$A$1:$A$2336,'Medical Examinations'!$B$1:$B$2336,0) -> 47.41 | D2: =_xlfn.XLOOKUP(A2,'Medical Examinations'!$A$1:$A$2336,'Medical Examinations'!$D$1:$D$2336,0) -> 7.47 | E2: =_xlfn.XLOOKUP(A2,'Medical Examinations'!$A$1:$A$2336,'Medical Examinations'!$E$1:$E$2336,0) -> No | F2: =_xlfn.XLOOKUP(A2,'Medical Examinations'!$A$1:$A$2336,'Medical Examinations'!$F$1:$F$2336,0) -> No | G2: =_xlfn.XLOOKUP(A2,'Medical Examinations'!$A$1:$A$2336,'Medical Examinations'!$G$1:$G$2336,0) -> No | H2: =_xlfn.XLOOKUP(A2,'Medical Examinations'!$A$1:$A$2336,'Medical Examinations'!$H$1:$H$2336,0) -> 0 | I2: =_xlfn.XLOOKUP(A2,'Medical Examinations'!$A$1:$A$2336,'Medical Examinations'!$I$1:$I$2336,0) -> Yes | J2: =_xlfn.XLOOKUP(A2,'Medical Examinations'!A2:A2345,'Medical Examinations'!C2:C2345,0) -> Obese | K2: =_xlfn.XLOOKUP(A2,'Medical Examinations'!$A$1:$A$2344,'Medical Examinations'!$D$1:$D$2344,0) -> 7.47 | L2: =_xlfn.XLOOKUP(A2,'Hospitalisation Details'!$A$1:$A$2344,'Hospitalisation Details'!$E$1:$E$2344,0) -> 12-Oct-1968 | M2: =_xlfn.XLOOKUP(A2,'Hospitalisation Details'!$A$1:$A$2344,'Hospitalisation Details'!$I$1:$I$2344,0) -> 63770.43 | N2: =_xlfn.XLOOKUP(A2,'Hospitalisation Details'!$A$1:$A$2344,'Hospitalisation Details'!$J$1:$J$2344,0) -> tier - 1 | O2: =_xlfn.XLOOKUP(A2,'Hospitalisation Details'!$A$1:$A$2344,'Hospitalisation Details'!$K$1:$K$2344,0) -> tier - 3 | P2: =_xlfn.XLOOKUP(A2,'Hospitalisation Details'!$A$1:$A$2344,'Hospitalisation Details'!$L$1:$L$2344,0) -> R1013 | Q2: =_xlfn.XLOOKUP(A2,'Hospitalisation Details'!$A$1:$A$2344,'Hospitalisation Details'!$F$1:$F$2344,0) -> 54
A3: Id2 | B3: =_xlfn.XLOOKUP(A3,'Customer Names'!$A$1:$A$2336,'Customer Names'!$C$1:$C$2336,0) -> Matthew D | C3: =_xlfn.XLOOKUP(A3,'Medical Examinations'!$A$1:$A$2336,'Medical Examinations'!$B$1:$B$2336,0) -> 30.36 | D3: =_xlfn.XLOOKUP(A3,'Medical Examinations'!$A$1:$A$2336,'Medical Examinations'!$D$1:$D$2336,0) -> 5.77 | E3: =_xlfn.XLOOKUP(A3,'Medical Examinations'!$A$1:$A$2336,'Medical Examinations'!$E$1:$E$2336,0) -> No | F3: =_xlfn.XLOOKUP(A3,'Medical Examinations'!$A$1:$A$2336,'Medical Examinations'!$F$1:$F$2336,0) -> No | G3: =_xlfn.XLOOKUP(A3,'Medical Examinations'!$A$1:$A$2336,'Medical Examinations'!$G$1:$G$2336,0) -> No | H3: =_xlfn.XLOOKUP(A3,'Medical Examinations'!$A$1:$A$2336,'Medical Examinations'!$H$1:$H$2336,0) -> 0 | I3: =_xlfn.XLOOKUP(A3,'Medical Examinations'!$A$1:$A$2336,'Medical Examinations'!$I$1:$I$2336,0) -> Yes | J3: =_xlfn.XLOOKUP(A3,'Medical Examinations'!A3:A2346,'Medical Examinations'!C3:C2346,0) -> Obese | K3: =_xlfn.XLOOKUP(A3,'Medical Examinations'!$A$1:$A$2344,'Medical Examinations'!$D$1:$D$2344,0) -> 5.77 | L3: =_xlfn.XLOOKUP(A3,'Hospitalisation Details'!$A$1:$A$2344,'Hospitalisation Details'!$E$1:$E$2344,0) -> 8-Jun-1977 | M3: =_xlfn.XLOOKUP(A3,'Hospitalisation Details'!$A$1:$A$2344,'Hospitalisation Details'!$I$1:$I$2344,0) -> 62592.87 | N3: =_xlfn.XLOOKUP(A3,'Hospitalisation Details'!$A$1:$A$2344,'Hospitalisation Details'!$J$1:$J$2344,0) -> tier - 2 | O3: =_xlfn.XLOOKUP(A3,'Hospitalisation Details'!$A$1:$A$2344,'Hospitalisation Details'!$K$1:$K$2344,0) -> tier - 3 | P3: =_xlfn.XLOOKUP(A3,'Hospitalisation Details'!$A$1:$A$2344,'Hospitalisation Details'!$L$1:$L$2344,0) -> R1013 | Q3: =_xlfn.XLOOKUP(A3,'Hospitalisation Details'!$A$1:$A$2344,'Hospitalisation Details'!$F$1:$F$2344,0) -> 46
A4: Id3 | B4: =_xlfn.XLOOKUP(A4,'Customer Names'!$A$1:$A$2336,'Customer Names'!$C$1:$C$2336,0) -> Phil | C4: =_xlfn.XLOOKUP(A4,'Medical Examinations'!$A$1:$A$2336,'Medical Examinations'!$B$1:$B$2336,0) -> 34.485 | D4: =_xlfn.XLOOKUP(A4,'Medical Examinations'!$A$1:$A$2336,'Medical Examinations'!$D$1:$D$2336,0) -> 11.87 | E4: =_xlfn.XLOOKUP(A4,'Medical Examinations'!$A$1:$A$2336,'Medical Examinations'!$E$1:$E$2336,0) -> No | F4: =_xlfn.XLOOKUP(A4,'Medical Examinations'!$A$1:$A$2336,'Medical Examinations'!$F$1:$F$2336,0) -> No | G4: =_xlfn.XLOOKUP(A4,'Medical Examinations'!$A$1:$A$2336,'Medical Examinations'!$G$1:$G$2336,0) -> No | H4: =_xlfn.XLOOKUP(A4,'Medical Examinations'!$A$1:$A$2336,'Medical Examinations'!$H$1:$H$2336,0) -> 2 | I4: =_xlfn.XLOOKUP(A4,'Medical Examinations'!$A$1:$A$2336,'Medical Examinations'!$I$1:$I$2336,0) -> Yes | J4: =_xlfn.XLOOKUP(A4,'Medical Examinations'!A4:A2347,'Medical Examinations'!C4:C2347,0) -> Obese | K4: =_xlfn.XLOOKUP(A4,'Medical Examinations'!$A$1:$A$2344,'Medical Examinations'!$D$1:$D$2344,0) -> 11.87 | L4: =_xlfn.XLOOKUP(A4,'Hospitalisation Details'!$A$1:$A$2344,'Hospitalisation Details'!$E$1:$E$2344,0) -> 11-Sep-1970 | M4: =_xlfn.XLOOKUP(A4,'Hospitalisation Details'!$A$1:$A$2344,'Hospitalisation Details'!$I$1:$I$2344,0) -> 60021.4 | N4: =_xlfn.XLOOKUP(A4,'Hospitalisation Details'!$A$1:$A$2344,'Hospitalisation Details'!$J$1:$J$2344,0) -> tier - 1 | O4: =_xlfn.XLOOKUP(A4,'Hospitalisation Details'!$A$1:$A$2344,'Hospitalisation Details'!$K$1:$K$2344,0) -> tier - 1 | P4: =_xlfn.XLOOKUP(A4,'Hospitalisation Details'!$A$1:$A$2344,'Hospitalisation Details'!$L$1:$L$2344,0) -> R1012 | Q4: =_xlfn.XLOOKUP(A4,'Hospitalisation Details'!$A$1:$A$2344,'Hospitalisation Details'!$F$1:$F$2344,0) -> 52
A5: Id4 | B5: =_xlfn.XLOOKUP(A5,'Customer Names'!$A$1:$A$2336,'Customer Names'!$C$1:$C$2336,0) -> Kelsey | C5: =_xlfn.XLOOKUP(A5,'Medical Examinations'!$A$1:$A$2336,'Medical Examinations'!$B$1:$B$2336,0) -> 38.095 | D5: =_xlfn.XLOOKUP(A5,'Medical Examinations'!$A$1:$A$2336,'Medical Examinations'!$D$1:$D$2336,0) -> 6.05 | E5: =_xlfn.XLOOKUP(A5,'Medical Examinations'!$A$1:$A$2336,'Medical Examinations'!$E$1:$E$2336,0) -> No | F5: =_xlfn.XLOOKUP(A5,'Medical Examinations'!$A$1:$A$2336,'Medical Examinations'!$F$1:$F$2336,0) -> No | G5: =_xlfn.XLOOKUP(A5,'Medical Examinations'!$A$1:$A$2336,'Medical Examinations'!$G$1:$G$2336,0) -> No | H5: =_xlfn.XLOOKUP(A5,'Medical Examinations'!$A$1:$A$2336,'Medical Examinations'!$H$1:$H$2336,0) -> 0 | I5: =_xlfn.XLOOKUP(A5,'Medical Examinations'!$A$1:$A$2336,'Medical Examinations'!$I$1:$I$2336,0) -> Yes | J5: =_xlfn.XLOOKUP(A5,'Medical Examinations'!A5:A2348,'Medical Examinations'!C5:C2348,0) -> Obese | K5: =_xlfn.XLOOKUP(A5,'Medical Examinations'!$A$1:$A$2344,'Medical Examinations'!$D$1:$D$2344,0) -> 6.05 | L5: =_xlfn.XLOOKUP(A5,'Hospitalisation Details'!$A$1:$A$2344,'Hospitalisation Details'!$E$1:$E$2344,0) -> 6-Jun-1991 | M5: =_xlfn.XLOOKUP(A5,'Hospitalisation Details'!$A$1:$A$2344,'Hospitalisation Details'!$I$1:$I$2344,0) -> 58571.07 | N5: =_xlfn.XLOOKUP(A5,'Hospitalisation Details'!$A$1:$A$2344,'Hospitalisation Details'!$J$1:$J$2344,0) -> tier - 1 | O5: =_xlfn.XLOOKUP(A5,'Hospitalisation Details'!$A$1:$A$2344,'Hospitalisation Details'!$K$1:$K$2344,0) -> tier - 3 | P5: =_xlfn.XLOOKUP(A5,'Hospitalisation Details'!$A$1:$A$2344,'Hospitalisation Details'!$L$1:$L$2344,0) -> R1024 | Q5: =_xlfn.XLOOKUP(A5,'Hospitalisation Details'!$A$1:$A$2344,'Hospitalisation Details'!$F$1:$F$2344,0) -> 32
A6: Id5 | B6: =_xlfn.XLOOKUP(A6,'Customer Names'!$A$1:$A$2336,'Customer Names'!$C$1:$C$2336,0) -> Kristyn | C6: =_xlfn.XLOOKUP(A6,'Medical Examinations'!$A$1:$A$2336,'Medical Examinations'!$B$1:$B$2336,0) -> 35.53 | D6: =_xlfn.XLOOKUP(A6,'Medical Examinations'!$A$1:$A$2336,'Medical Examinations'!$D$1:$D$2336,0) -> 5.45 | E6: =_xlfn.XLOOKUP(A6,'Medical Examinations'!$A$1:$A$2336,'Medical Examinations'!$E$1:$E$2336,0) -> No | F6: =_xlfn.XLOOKUP(A6,'Medical Examinations'!$A$1:$A$2336,'Medical Examinations'!$F$1:$F$2336,0) -> No | G6: =_xlfn.XLOOKUP(A6,'Medical Examinations'!$A$1:$A$2336,'Medical Examinations'!$G$1:$G$2336,0) -> No | H6: =_xlfn.XLOOKUP(A6,'Medical Examinations'!$A$1:$A$2336,'Medical Examinations'!$H$1:$H$2336,0) -> 0 | I6: =_xlfn.XLOOKUP(A6,'Medical Examinations'!$A$1:$A$2336,'Medical Examinations'!$I$1:$I$2336,0) -> Yes | J6: =_xlfn.XLOOKUP(A6,'Medical Examinations'!A6:A2349,'Medical Examinations'!C6:C2349,0) -> Obese | K6: =_xlfn.XLOOKUP(A6,'Medical Examinations'!$A$1:$A$2344,'Medical Examinations'!$D$1:$D$2344,0) -> 5.45 | L6: =_xlfn.XLOOKUP(A6,'Hospitalisation Details'!$A$1:$A$2344,'Hospitalisation Details'!$E$1:$E$2344,0) -> 19-Jun-1989 | M6: =_xlfn.XLOOKUP(A6,'Hospitalisation Details'!$A$1:$A$2344,'Hospitalisation Details'!$I$1:$I$2344,0) -> 55135.4 | N6: =_xlfn.XLOOKUP(A6,'Hospitalisation Details'!$A$1:$A$2344,'Hospitalisation Details'!$J$1:$J$2344,0) -> tier - 1 | O6: =_xlfn.XLOOKUP(A6,'Hospitalisation Details'!$A$1:$A$2344,'Hospitalisation Details'!$K$1:$K$2344,0) -> tier - 2 | P6: =_xlfn.XLOOKUP(A6,'Hospitalisation Details'!$A$1:$A$2344,'Hospitalisation Details'!$L$1:$L$2344,0) -> R1012 | Q6: =_xlfn.XLOOKUP(A6,'Hospitalisation Details'!$A$1:$A$2344,'Hospitalisation Details'!$F$1:$F$2344,0) -> 33
A7: Id6 | B7: =_xlfn.XLOOKUP(A7,'Customer Names'!$A$1:$A$2336,'Customer Names'!$C$1:$C$2336,0) -> Russell B | C7: =_xlfn.XLOOKUP(A7,'Medical Examinations'!$A$1:$A$2336,'Medical Examinations'!$B$1:$B$2336,0) -> 32.8 | D7: =_xlfn.XLOOKUP(A7,'Medical Examinations'!$A$1:$A$2336,'Medical Examinations'!$D$1:$D$2336,0) -> 6.59 | E7: =_xlfn.XLOOKUP(A7,'Medical Examinations'!$A$1:$A$2336,'Medical Examinations'!$E$1:$E$2336,0) -> No | F7: =_xlfn.XLOOKUP(A7,'Medical Examinations'!$A$1:$A$2336,'Medical Examinations'!$F$1:$F$2336,0) -> No | G7: =_xlfn.XLOOKUP(A7,'Medical Examinations'!$A$1:$A$2336,'Medical Examinations'!$G$1:$G$2336,0) -> No | H7: =_xlfn.XLOOKUP(A7,'Medical Examinations'!$A$1:$A$2336,'Medical Examinations'!$H$1:$H$2336,0) -> 0 | I7: =_xlfn.XLOOKUP(A7,'Medical Examinations'!$A$1:$A$2336,'Medical Examinations'!$I$1:$I$2336,0) -> Yes | J7: =_xlfn.XLOOKUP(A7,'Medical Examinations'!A7:A2350,'Medical Examinations'!C7:C2350,0) -> Obese | K7: =_xlfn.XLOOKUP(A7,'Medical Examinations'!$A$1:$A$2344,'Medical Examinations'!$D$1:$D$2344,0) -> 6.59 | L7: =_xlfn.XLOOKUP(A7,'Hospitalisation Details'!$A$1:$A$2344,'Hospitalisation Details'!$E$1:$E$2344,0) -> 4-Aug-1962 | M7: =_xlfn.XLOOKUP(A7,'Hospitalisation Details'!$A$1:$A$2344,'Hospitalisation Details'!$I$1:$I$2344,0) -> 52590.83 | N7: =_xlfn.XLOOKUP(A7,'Hospitalisation Details'!$A$1:$A$2344,'Hospitalisation Details'!$J$1:$J$2344,0) -> tier - 1 | O7: =_xlfn.XLOOKUP(A7,'Hospitalisation Details'!$A$1:$A$2344,'Hospitalisation Details'!$K$1:$K$2344,0) -> tier - 3 | P7: =_xlfn.XLOOKUP(A7,'Hospitalisation Details'!$A$1:$A$2344,'Hospitalisation Details'!$L$1:$L$2344,0) -> R1011 | Q7: =_xlfn.XLOOKUP(A7,'Hospitalisation Details'!$A$1:$A$2344,'Hospitalisation Details'!$F$1:$F$2344,0) -> 60
A8: Id7 | B8: =_xlfn.XLOOKUP(A8,'Customer Names'!$A$1:$A$2336,'Customer Names'!$C$1:$C$2336,0) -> Scott | C8: =_xlfn.XLOOKUP(A8,'Medical Examinations'!$A$1:$A$2336,'Medical Examinations'!$B$1:$B$2336,0) -> 36.4 | D8: =_xlfn.XLOOKUP(A8,'Medical Examinations'!$A$1:$A$2336,'Medical Examinations'!$D$1:$D$2336,0) -> 6.07 | E8: =_xlfn.XLOOKUP(A8,'Medical Examinations'!$A$1:$A$2336,'Medical Examinations'!$E$1:$E$2336,0) -> No | F8: =_xlfn.XLOOKUP(A8,'Medical Examinations'!$A$1:$A$2336,'Medical Examinations'!$F$1:$F$2336,0) -> No | G8: =_xlfn.XLOOKUP(A8,'Medical Examinations'!$A$1:$A$2336,'Medical Examinations'!$G$1:$G$2336,0) -> No | H8: =_xlfn.XLOOKUP(A8,'Medical Examinations'!$A$1:$A$2336,'Medical Examinations'!$H$1:$H$2336,0) -> 0 | I8: =_xlfn.XLOOKUP(A8,'Medical Examinations'!$A$1:$A$2336,'Medical Examinations'!$I$1:$I$2336,0) -> Yes | J8: =_xlfn.XLOOKUP(A8,'Medical Examinations'!A8:A2351,'Medical Examinations'!C8:C2351,0) -> Obese | K8: =_xlfn.XLOOKUP(A8,'Medical Examinations'!$A$1:$A$2344,'Medical Examinations'!$D$1:$D$2344,0) -> 6.07 | L8: =_xlfn.XLOOKUP(A8,'Hospitalisation Details'!$A$1:$A$2344,'Hospitalisation Details'!$E$1:$E$2344,0) -> 27-Oct-1994 | M8: =_xlfn.XLOOKUP(A8,'Hospitalisation Details'!$A$1:$A$2344,'Hospitalisation Details'!$I$1:$I$2344,0) -> 51194.56 | N8: =_xlfn.XLOOKUP(A8,'Hospitalisation Details'!$A$1:$A$2344,'Hospitalisation Details'!$J$1:$J$2344,0) -> tier - 1 | O8: =_xlfn.XLOOKUP(A8,'Hospitalisation Details'!$A$1:$A$2344,'Hospitalisation Details'!$K$1:$K$2344,0) -> tier - 3 | P8: =_xlfn.XLOOKUP(A8,'Hospitalisation Details'!$A$1:$A$2344,'Hospitalisation Details'!$L$1:$L$2344,0) -> R1011 | Q8: =_xlfn.XLOOKUP(A8,'Hospitalisation Details'!$A$1:$A$2344,'Hospitalisation Details'!$F$1:$F$2344,0) -> 28
A9: Id8 | B9: =_xlfn.XLOOKUP(A9,'Customer Names'!$A$1:$A$2336,'Customer Names'!$C$1:$C$2336,0) -> Stephen | C9: =_xlfn.XLOOKUP(A9,'Medical Examinations'!$A$1:$A$2336,'Medical Examinations'!$B$1:$B$2336,0) -> 36.96 | D9: =_xlfn.XLOOKUP(A9,'Medical Examinations'!$A$1:$A$2336,'Medical Examinations'!$D$1:$D$2336,0) -> 7.93 | E9: =_xlfn.XLOOKUP(A9,'Medical Examinations'!$A$1:$A$2336,'Medical Examinations'!$E$1:$E$2336,0) -> No | F9: =_xlfn.XLOOKUP(A9,'Medical Examinations'!$A$1:$A$2336,'Medical Examinations'!$F$1:$F$2336,0) -> No | G9: =_xlfn.XLOOKUP(A9,'Medical Examinations'!$A$1:$A$2336,'Medical Examinations'!$G$1:$G$2336,0) -> No | H9: =_xlfn.XLOOKUP(A9,'Medical Examinations'!$A$1:$A$2336,'Medical Examinations'!$H$1:$H$2336,0) -> 3 | I9: =_xlfn.XLOOKUP(A9,'Medical Examinations'!$A$1:$A$2336,'Medical Examinations'!$I$1:$I$2336,0) -> Yes | J9: =_xlfn.XLOOKUP(A9,'Medical Examinations'!A9:A2352,'Medical Examinations'!C9:C2352,0) -> Obese | K9: =_xlfn.XLOOKUP(A9,'Medical Examinations'!$A$1:$A$2344,'Medical Examinations'!$D$1:$D$2344,0) -> 7.93 | L9: =_xlfn.XLOOKUP(A9,'Hospitalisation Details'!$A$1:$A$2344,'Hospitalisation Details'!$E$1:$E$2344,0) -> 27-Jun-1958 | M9: =_xlfn.XLOOKUP(A9,'Hospitalisation Details'!$A$1:$A$2344,'Hospitalisation Details'!$I$1:$I$2344,0) -> 49577.66 | N9: =_xlfn.XLOOKUP(A9,'Hospitalisation Details'!$A$1:$A$2344,'Hospitalisation Details'!$J$1:$J$2344,0) -> tier - 2 | O9: =_xlfn.XLOOKUP(A9,'Hospitalisation Details'!$A$1:$A$2344,'Hospitalisation Details'!$K$1:$K$2344,0) -> tier - 2 | P9: =_xlfn.XLOOKUP(A9,'Hospitalisation Details'!$A$1:$A$2344,'Hospitalisation Details'!$L$1:$L$2344,0) -> R1013 | Q9: =_xlfn.XLOOKUP(A9,'Hospitalisation Details'!$A$1:$A$2344,'Hospitalisation Details'!$F$1:$F$2344,0) -> 64
A10: Id9 | B10: =_xlfn.XLOOKUP(A10,'Customer Names'!$A$1:$A$2336,'Customer Names'!$C$1:$C$2336,0) -> Patrick R | C10: =_xlfn.XLOOKUP(A10,'Medical Examinations'!$A$1:$A$2336,'Medical Examinations'!$B$1:$B$2336,0) -> 41.14 | D10: =_xlfn.XLOOKUP(A10,'Medical Examinations'!$A$1:$A$2336,'Medical Examinations'!$D$1:$D$2336,0) -> 9.58 | E10: =_xlfn.XLOOKUP(A10,'Medical Examinations'!$A$1:$A$2336,'Medical Examinations'!$E$1:$E$2336,0) -> No | F10: =_xlfn.XLOOKUP(A10,'Medical Examinations'!$A$1:$A$2336,'Medical Examinations'!$F$1:$F$2336,0) -> No | G10: =_xlfn.XLOOKUP(A10,'Medical Examinations'!$A$1:$A$2336,'Medical Examinations'!$G$1:$G$2336,0) -> Yes | H10: =_xlfn.XLOOKUP(A10,'Medical Examinations'!$A$1:$A$2336,'Medical Examinations'!$H$1:$H$2336,0) -> 1 | I10: =_xlfn.XLOOKUP(A10,'Medical Examinations'!$A$1:$A$2336,'Medical Examinations'!$I$1:$I$2336,0) -> Yes | J10: =_xlfn.XLOOKUP(A10,'Medical Examinations'!A10:A2353,'Medical Examinations'!C10:C2353,0) -> Obese | K10: =_xlfn.XLOOKUP(A10,'Medical Examinations'!$A$1:$A$2344,'Medical Examinations'!$D$1:$D$2344,0) -> 9.58 | L10: =_xlfn.XLOOKUP(A10,'Hospitalisation Details'!$A$1:$A$2344,'Hospitalisation Details'!$E$1:$E$2344,0) -> 4-Sep-1963 | M10: =_xlfn.XLOOKUP(A10,'Hospitalisation Details'!$A$1:$A$2344,'Hospitalisation Details'!$I$1:$I$2344,0) -> 48970.25 | N10: =_xlfn.XLOOKUP(A10,'Hospitalisation Details'!$A$1:$A$2344,'Hospitalisation Details'!$J$1:$J$2344,0) -> tier - 1 | O10: =_xlfn.XLOOKUP(A10,'Hospitalisation Details'!$A$1:$A$2344,'Hospitalisation Details'!$K$1:$K$2344,0) -> tier - 2 | P10: =_xlfn.XLOOKUP(A10,'Hospitalisation Details'!$A$1:$A$2344,'Hospitalisation Details'!$L$1:$L$2344,0) -> R1013 | Q10: =_xlfn.XLOOKUP(A10,'Hospitalisation Details'!$A$1:$A$2344,'Hospitalisation Details'!$F$1:$F$2344,0) -> 59
A11: Id10 | B11: =_xlfn.XLOOKUP(A11,'Customer Names'!$A$1:$A$2336,'Customer Names'!$C$1:$C$2336,0) -> Brooke N | C11: =_xlfn.XLOOKUP(A11,'Medical Examinations'!$A$1:$A$2336,'Medical Examinations'!$B$1:$B$2336,0) -> 38.06 | D11: =_xlfn.XLOOKUP(A11,'Medical Examinations'!$A$1:$A$2336,'Medical Examinations'!$D$1:$D$2336,0) -> 10.79 | E11: =_xlfn.XLOOKUP(A11,'Medical Examinations'!$A$1:$A$2336,'Medical Examinations'!$E$1:$E$2336,0) -> No | F11: =_xlfn.XLOOKUP(A11,'Medical Examinations'!$A$1:$A$2336,'Medical Examinations'!$F$1:$F$2336,0) -> No | G11: =_xlfn.XLOOKUP(A11,'Medical Examinations'!$A$1:$A$2336,'Medical Examinations'!$G$1:$G$2336,0) -> No | H11: =_xlfn.XLOOKUP(A11,'Medical Examinations'!$A$1:$A$2336,'Medical Examinations'!$H$1:$H$2336,0) -> 0 | I11: =_xlfn.XLOOKUP(A11,'Medical Examinations'!$A$1:$A$2336,'Medical Examinations'!$I$1:$I$2336,0) -> Yes | J11: =_xlfn.XLOOKUP(A11,'Medical Examinations'!A11:A2354,'Medical Examinations'!C11:C2354,0) -> Obese | K11: =_xlfn.XLOOKUP(A11,'Medical Examinations'!$A$1:$A$2344,'Medical Examinations'!$D$1:$D$2344,0) -> 10.79 | L11: =_xlfn.XLOOKUP(A11,'Hospitalisation Details'!$A$1:$A$2344,'Hospitalisation Details'!$E$1:$E$2344,0) -> 29-Dec-1978 | M11: =_xlfn.XLOOKUP(A11,'Hospitalisation Details'!$A$1:$A$2344,'Hospitalisation Details'!$I$1:$I$2344,0) -> 48885.14 | N11: =_xlfn.XLOOKUP(A11,'Hospitalisation Details'!$A$1:$A$2344,'Hospitalisation Details'!$J$1:$J$2344,0) -> tier - 1 | O11: =_xlfn.XLOOKUP(A11,'Hospitalisation Details'!$A$1:$A$2344,'Hospitalisation Details'!$K$1:$K$2344,0) -> tier - 2 | P11: =_xlfn.XLOOKUP(A11,'Hospitalisation Details'!$A$1:$A$2344,'Hospitalisation Details'!$L$1:$L$2344,0) -> R1013 | Q11: =_xlfn.XLOOKUP(A11,'Hospitalisation Details'!$A$1:$A$2344,'Hospitalisation Details'!$F$1:$F$2344,0) -> 44
A12: Id11 | B12: =_xlfn.XLOOKUP(A12,'Customer Names'!$A$1:$A$2336,'Customer Names'!$C$1:$C$2336,0) -> Paola Andrea | C12: =_xlfn.XLOOKUP(A12,'Medical Examinations'!$A$1:$A$2336,'Medical Examinations'!$B$1:$B$2336,0) -> 37.7 | D12: =_xlfn.XLOOKUP(A12,'Medical Examinations'!$A$1:$A$2336,'Medical Examinations'!$D$1:$D$2336,0) -> 5.96 | E12: =_xlfn.XLOOKUP(A12,'Medical Examinations'!$A$1:$A$2336,'Medical Examinations'!$E$1:$E$2336,0) -> No | F12: =_xlfn.XLOOKUP(A12,'Medical Examinations'!$A$1:$A$2336,'Medical Examinations'!$F$1:$F$2336,0) -> No | G12: =_xlfn.XLOOKUP(A12,'Medical Examinations'!$A$1:$A$2336,'Medical Examinations'!$G$1:$G$2336,0) -> No | H12: =_xlfn.XLOOKUP(A12,'Medical Examinations'!$A$1:$A$2336,'Medical Examinations'!$H$1:$H$2336,0) -> 2 | I12: =_xlfn.XLOOKUP(A12,'Medical Examinations'!$A$1:$A$2336,'Medical Examinations'!$I$1:$I$2336,0) -> Yes | J12: =_xlfn.XLOOKUP(A12,'Medical Examinations'!A12:A2355,'Medical Examinations'!C12:C2355,0) -> Obese | K12: =_xlfn.XLOOKUP(A12,'Medical Examinations'!$A$1:$A$2344,'Medical Examinations'!$D$1:$D$2344,0) -> 5.96 | L12: =_xlfn.XLOOKUP(A12,'Hospitalisation Details'!$A$1:$A$2344,'Hospitalisation Details'!$E$1:$E$2344,0) -> 22-Jul-1959 | M12: =_xlfn.XLOOKUP(A12,'Hospitalisation Details'!$A$1:$A$2344,'Hospitalisation Details'!$I$1:$I$2344,0) -> 48824.45 | N12: =_xlfn.XLOOKUP(A12,'Hospitalisation Details'!$A$1:$A$2344,'Hospitalisation Details'!$J$1:$J$2344,0) -> tier - 2 | O12: =_xlfn.XLOOKUP(A12,'Hospitalisation Details'!$A$1:$A$2344,'Hospitalisation Details'!$K$1:$K$2344,0) -> tier - 1 | P12: =_xlfn.XLOOKUP(A12,'Hospitalisation Details'!$A$1:$A$2344,'Hospitalisation Details'!$L$1:$L$2344,0) -> R1011 | Q12: =_xlfn.XLOOKUP(A12,'Hospitalisation Details'!$A$1:$A$2344,'Hospitalisation Details'!$F$1:$F$2344,0) -> 63
... A17: Id16 | B17: =_xlfn.XLOOKUP(A17,'Customer Names'!$A$1:$A$2336,'Customer Names'!$C$1:$C$2336,0) -> Philippe | C17: =_xlfn.XLOOKUP(A17,'Medical Examinations'!$A$1:$A$2336,'Medical Examinations'!$B$1:$B$2336,0) -> 39.9 | D17: =_xlfn.XLOOKUP(A17,'Medical Examinations'!$A$1:$A$2336,'Medical Examinations'!$D$1:$D$2336,0) -> 11.32 | E17: =_xlfn.XLOOKUP(A17,'Medical Examinations'!$A$1:$A$2336,'Medical Examinations'!$E$1:$E$2336,0) -> No | F17: =_xlfn.XLOOKUP(A17,'Medical Examinations'!$A$1:$A$2336,'Medical Examinations'!$F$1:$F$2336,0) -> No | G17: =_xlfn.XLOOKUP(A17,'Medical Examinations'!$A$1:$A$2336,'Medical Examinations'!$G$1:$G$2336,0) -> No | H17: =_xlfn.XLOOKUP(A17,'Medical Examinations'!$A$1:$A$2336,'Medical Examinations'!$H$1:$H$2336,0) -> 0 | I17: =_xlfn.XLOOKUP(A17,'Medical Examinations'!$A$1:$A$2336,'Medical Examinations'!$I$1:$I$2336,0) -> Yes | J17: =_xlfn.XLOOKUP(A17,'Medical Examinations'!A17:A2360,'Medical Examinations'!C17:C2360,0) -> Obese | K17: =_xlfn.XLOOKUP(A17,'Medical Examinations'!$A$1:$A$2344,'Medical Examinations'!$D$1:$D$2344,0) -> 11.32 | L17: =_xlfn.XLOOKUP(A17,'Hospitalisation Details'!$A$1:$A$2344,'Hospitalisation Details'!$E$1:$E$2344,0) -> 27-Aug-1962 | M17: =_xlfn.XLOOKUP(A17,'Hospitalisation Details'!$A$1:$A$2344,'Hospitalisation Details'!$I$1:$I$2344,0) -> 48173.36 | N17: =_xlfn.XLOOKUP(A17,'Hospitalisation Details'!$A$1:$A$2344,'Hospitalisation Details'!$J$1:$J$2344,0) -> tier - 1 | O17: =_xlfn.XLOOKUP(A17,'Hospitalisation Details'!$A$1:$A$2344,'Hospitalisation Details'!$K$1:$K$2344,0) -> tier - 3 | P17: =_xlfn.XLOOKUP(A17,'Hospitalisation Details'!$A$1:$A$2344,'Hospitalisation Details'!$L$1:$L$2344,0) -> R1011 | Q17: =_xlfn.XLOOKUP(A17,'Hospitalisation Details'!$A$1:$A$2344,'Hospitalisation Details'!$F$1:$F$2344,0) -> 60
A18: Id17 | B18: =_xlfn.XLOOKUP(A18,'Customer Names'!$A$1:$A$2336,'Customer Names'!$C$1:$C$2336,0) -> Jennifer A | D18: =_xlfn.XLOOKUP(A18,'Medical Examinations'!$A$1:$A$2336,'Medical Examinations'!$D$1:$D$2336,0) -> 7.67 | E18: =_xlfn.XLOOKUP(A18,'Medical Examinations'!$A$1:$A$2336,'Medical Examinations'!$E$1:$E$2336,0) -> No | F18: =_xlfn.XLOOKUP(A18,'Medical Examinations'!$A$1:$A$2336,'Medical Examinations'!$F$1:$F$2336,0) -> No | G18: =_xlfn.XLOOKUP(A18,'Medical Examinations'!$A$1:$A$2336,'Medical Examinations'!$G$1:$G$2336,0) -> No | H18: =_xlfn.XLOOKUP(A18,'Medical Examinations'!$A$1:$A$2336,'Medical Examinations'!$H$1:$H$2336,0) -> 3 | I18: =_xlfn.XLOOKUP(A18,'Medical Examinations'!$A$1:$A$2336,'Medical Examinations'!$I$1:$I$2336,0) -> Yes | J18: =_xlfn.XLOOKUP(A18,'Medical Examinations'!A18:A2361,'Medical Examinations'!C18:C2361,0) -> Obese | K18: =_xlfn.XLOOKUP(A18,'Medical Examinations'!$A$1:$A$2344,'Medical Examinations'!$D$1:$D$2344,0) -> 7.67 | L18: =_xlfn.XLOOKUP(A18,'Hospitalisation Details'!$A$1:$A$2344,'Hospitalisation Details'!$E$1:$E$2344,0) -> 16-Nov-1958 | M18: =_xlfn.XLOOKUP(A18,'Hospitalisation Details'!$A$1:$A$2344,'Hospitalisation Details'!$I$1:$I$2344,0) -> 47928.03 | N18: =_xlfn.XLOOKUP(A18,'Hospitalisation Details'!$A$1:$A$2344,'Hospitalisation Details'!$J$1:$J$2344,0) -> tier - 2 | O18: =_xlfn.XLOOKUP(A18,'Hospitalisation Details'!$A$1:$A$2344,'Hospitalisation Details'!$K$1:$K$2344,0) -> tier - 3 | P18: =_xlfn.XLOOKUP(A18,'Hospitalisation Details'!$A$1:$A$2344,'Hospitalisation Details'!$L$1:$L$2344,0) -> R1011 | Q18: =_xlfn.XLOOKUP(A18,'Hospitalisation Details'!$A$1:$A$2344,'Hospitalisation Details'!$F$1:$F$2344,0) -> 64
A19: Id18 | B19: =_xlfn.XLOOKUP(A19,'Customer Names'!$A$1:$A$2336,'Customer Names'!$C$1:$C$2336,0) -> Christina M | C19: =_xlfn.XLOOKUP(A19,'Medical Examinations'!$A$1:$A$2336,'Medical Examinations'!$B$1:$B$2336,0) -> 36.765 | D19: =_xlfn.XLOOKUP(A19,'Medical Examinations'!$A$1:$A$2336,'Medical Examinations'!$D$1:$D$2336,0) -> 7.29 | E19: =_xlfn.XLOOKUP(A19,'Medical Examinations'!$A$1:$A$2336,'Medical Examinations'!$E$1:$E$2336,0) -> No | F19: =_xlfn.XLOOKUP(A19,'Medical Examinations'!$A$1:$A$2336,'Medical Examinations'!$F$1:$F$2336,0) -> No | G19: =_xlfn.XLOOKUP(A19,'Medical Examinations'!$A$1:$A$2336,'Medical Examinations'!$G$1:$G$2336,0) -> Yes | H19: =_xlfn.XLOOKUP(A19,'Medical Examinations'!$A$1:$A$2336,'Medical Examinations'!$H$1:$H$2336,0) -> 1 | I19: =_xlfn.XLOOKUP(A19,'Medical Examinations'!$A$1:$A$2336,'Medical Examinations'!$I$1:$I$2336,0) -> Yes | J19: =_xlfn.XLOOKUP(A19,'Medical Examinations'!A19:A2362,'Medical Examinations'!C19:C2362,0) -> Obese | K19: =_xlfn.XLOOKUP(A19,'Medical Examinations'!$A$1:$A$2344,'Medical Examinations'!$D$1:$D$2344,0) -> 7.29 | L19: =_xlfn.XLOOKUP(A19,'Hospitalisation Details'!$A$1:$A$2344,'Hospitalisation Details'!$E$1:$E$2344,0) -> 5-Aug-1963 | M19: =_xlfn.XLOOKUP(A19,'Hospitalisation Details'!$A$1:$A$2344,'Hospitalisation Details'!$I$1:$I$2344,0) -> 47896.79 | N19: =_xlfn.XLOOKUP(A19,'Hospitalisation Details'!$A$1:$A$2344,'Hospitalisation Details'!$J$1:$J$2344,0) -> tier - 1 | O19: =_xlfn.XLOOKUP(A19,'Hospitalisation Details'!$A$1:$A$2344,'Hospitalisation Details'!$K$1:$K$2344,0) -> tier - 3 | P19: =_xlfn.XLOOKUP(A19,'Hospitalisation Details'!$A$1:$A$2344,'Hospitalisation Details'!$L$1:$L$2344,0) -> R1024 | Q19: =_xlfn.XLOOKUP(A19,'Hospitalisation Details'!$A$1:$A$2344,'Hospitalisation Details'!$F$1:$F$2344,0) -> 59
A20: Id19 | B20: =_xlfn.XLOOKUP(A20,'Customer Names'!$A$1:$A$2336,'Customer Names'!$C$1:$C$2336,0) -> Said Sr | D20: =_xlfn.XLOOKUP(A20,'Medical Examinations'!$A$1:$A$2336,'Medical Examinations'!$D$1:$D$2336,0) -> 4.72 | E20: =_xlfn.XLOOKUP(A20,'Medical Examinations'!$A$1:$A$2336,'Medical Examinations'!$E$1:$E$2336,0) -> No | F20: =_xlfn.XLOOKUP(A20,'Medical Examinations'!$A$1:$A$2336,'Medical Examinations'!$F$1:$F$2336,0) -> No | G20: =_xlfn.XLOOKUP(A20,'Medical Examinations'!$A$1:$A$2336,'Medical Examinations'!$G$1:$G$2336,0) -> No | H20: =_xlfn.XLOOKUP(A20,'Medical Examinations'!$A$1:$A$2336,'Medical Examinations'!$H$1:$H$2336,0) -> 1 | I20: =_xlfn.XLOOKUP(A20,'Medical Examinations'!$A$1:$A$2336,'Medical Examinations'!$I$1:$I$2336,0) -> Yes | J20: =_xlfn.XLOOKUP(A20,'Medical Examinations'!A20:A2363,'Medical Examinations'!C20:C2363,0) -> Obese | K20: =_xlfn.XLOOKUP(A20,'Medical Examinations'!$A$1:$A$2344,'Medical Examinations'!$D$1:$D$2344,0) -> 4.72 | L20: =_xlfn.XLOOKUP(A20,'Hospitalisation Details'!$A$1:$A$2344,'Hospitalisation Details'!$E$1:$E$2344,0) -> 7-Nov-1964 | M20: =_xlfn.XLOOKUP(A20,'Hospitalisation Details'!$A$1:$A$2344,'Hospitalisation Details'!$I$1:$I$2344,0) -> 47496.49 | N20: =_xlfn.XLOOKUP(A20,'Hospitalisation Details'!$A$1:$A$2344,'Hospitalisation Details'!$J$1:$J$2344,0) -> tier - 1 | O20: =_xlfn.XLOOKUP(A20,'Hospitalisation Details'!$A$1:$A$2344,'Hospitalisation Details'!$K$1:$K$2344,0) -> tier - 3 | P20: =_xlfn.XLOOKUP(A20,'Hospitalisation Details'!$A$1:$A$2344,'Hospitalisation Details'!$L$1:$L$2344,0) -> R1012 | Q20: =_xlfn.XLOOKUP(A20,'Hospitalisation Details'!$A$1:$A$2344,'Hospitalisation Details'!$F$1:$F$2344,0) -> 58
A21: Id20 | B21: =_xlfn.XLOOKUP(A21,'Customer Names'!$A$1:$A$2336,'Customer Names'!$C$1:$C$2336,0) -> John | C21: =_xlfn.XLOOKUP(A21,'Medical Examinations'!$A$1:$A$2336,'Medical Examinations'!$B$1:$B$2336,0) -> 42.9 | D21: =_xlfn.XLOOKUP(A21,'Medical Examinations'!$A$1:$A$2336,'Medical Examinations'!$D$1:$D$2336,0) -> 11.41 | E21: =_xlfn.XLOOKUP(A21,'Medical Examinations'!$A$1:$A$2336,'Medical Examinations'!$E$1:$E$2336,0) -> No | F21: =_xlfn.XLOOKUP(A21,'Medical Examinations'!$A$1:$A$2336,'Medical Examinations'!$F$1:$F$2336,0) -> No | G21: =_xlfn.XLOOKUP(A21,'Medical Examinations'!$A$1:$A$2336,'Medical Examinations'!$G$1:$G$2336,0) -> No | H21: =_xlfn.XLOOKUP(A21,'Medical Examinations'!$A$1:$A$2336,'Medical Examinations'!$H$1:$H$2336,0) -> 0 | I21: =_xlfn.XLOOKUP(A21,'Medical Examinations'!$A$1:$A$2336,'Medical Examinations'!$I$1:$I$2336,0) -> Yes | J21: =_xlfn.XLOOKUP(A21,'Medical Examinations'!A21:A2364,'Medical Examinations'!C21:C2364,0) -> Obese | K21: =_xlfn.XLOOKUP(A21,'Medical Examinations'!$A$1:$A$2344,'Medical Examinations'!$D$1:$D$2344,0) -> 11.41 | L21: =_xlfn.XLOOKUP(A21,'Hospitalisation Details'!$A$1:$A$2344,'Hospitalisation Details'!$E$1:$E$2344,0) -> 27-Sep-1971 | M21: =_xlfn.XLOOKUP(A21,'Hospitalisation Details'!$A$1:$A$2344,'Hospitalisation Details'!$I$1:$I$2344,0) -> 47462.89 | N21: =_xlfn.XLOOKUP(A21,'Hospitalisation Details'!$A$1:$A$2344,'Hospitalisation Details'!$J$1:$J$2344,0) -> tier - 1 | O21: =_xlfn.XLOOKUP(A21,'Hospitalisation Details'!$A$1:$A$2344,'Hospitalisation Details'!$K$1:$K$2344,0) -> tier - 2 | P21: =_xlfn.XLOOKUP(A21,'Hospitalisation Details'!$A$1:$A$2344,'Hospitalisation Details'!$L$1:$L$2344,0) -> R1013 | Q21: =_xlfn.XLOOKUP(A21,'Hospitalisation Details'!$A$1:$A$2344,'Hospitalisation Details'!$F$1:$F$2344,0) -> 51
A22: Id21 | B22: =_xlfn.XLOOKUP(A22,'Customer Names'!$A$1:$A$2336,'Customer Names'!$C$1:$C$2336,0) -> Myles | C22: =_xlfn.XLOOKUP(A22,'Medical Examinations'!$A$1:$A$2336,'Medical Examinations'!$B$1:$B$2336,0) -> 36.3 | D22: =_xlfn.XLOOKUP(A22,'Medical Examinations'!$A$1:$A$2336,'Medical Examinations'!$D$1:$D$2336,0) -> 11.5 | E22: =_xlfn.XLOOKUP(A22,'Medical Examinations'!$A$1:$A$2336,'Medical Examinations'!$E$1:$E$2336,0) -> No | F22: =_xlfn.XLOOKUP(A22,'Medical Examinations'!$A$1:$A$2336,'Medical Examinations'!$F$1:$F$2336,0) -> No | G22: =_xlfn.XLOOKUP(A22,'Medical Examinations'!$A$1:$A$2336,'Medical Examinations'!$G$1:$G$2336,0) -> No | H22: =_xlfn.XLOOKUP(A22,'Medical Examinations'!$A$1:$A$2336,'Medical Examinations'!$H$1:$H$2336,0) -> 2 | I22: =_xlfn.XLOOKUP(A22,'Medical Examinations'!$A$1:$A$2336,'Medical Examinations'!$I$1:$I$2336,0) -> Yes | J22: =_xlfn.XLOOKUP(A22,'Medical Examinations'!A22:A2365,'Medical Examinations'!C22:C2365,0) -> Obese | K22: =_xlfn.XLOOKUP(A22,'Medical Examinations'!$A$1:$A$2344,'Medical Examinations'!$D$1:$D$2344,0) -> 11.5 | L22: =_xlfn.XLOOKUP(A22,'Hospitalisation Details'!$A$1:$A$2344,'Hospitalisation Details'!$E$1:$E$2344,0) -> 13-Jun-1961 | M22: =_xlfn.XLOOKUP(A22,'Hospitalisation Details'!$A$1:$A$2344,'Hospitalisation Details'!$I$1:$I$2344,0) -> 47403.88 | N22: =_xlfn.XLOOKUP(A22,'Hospitalisation Details'!$A$1:$A$2344,'Hospitalisation Details'!$J$1:$J$2344,0) -> tier - 1 | O22: =_xlfn.XLOOKUP(A22,'Hospitalisation Details'!$A$1:$A$2344,'Hospitalisation Details'!$K$1:$K$2344,0) -> tier - 3 | P22: =_xlfn.XLOOKUP(A22,'Hospitalisation Details'!$A$1:$A$2344,'Hospitalisation Details'!$L$1:$L$2344,0) -> R1011 | Q22: =_xlfn.XLOOKUP(A22,'Hospitalisation Details'!$A$1:$A$2344,'Hospitalisation Details'!$F$1:$F$2344,0) -> 62
A23: Id22 | B23: =_xlfn.XLOOKUP(A23,'Customer Names'!$A$1:$A$2336,'Customer Names'!$C$1:$C$2336,0) -> Madelyn C | C23: =_xlfn.XLOOKUP(A23,'Medical Examinations'!$A$1:$A$2336,'Medical Examinations'!$B$1:$B$2336,0) -> 32.2 | D23: =_xlfn.XLOOKUP(A23,'Medical Examinations'!$A$1:$A$2336,'Medical Examinations'!$D$1:$D$2336,0) -> 6.22 | E23: =_xlfn.XLOOKUP(A23,'Medical Examinations'!$A$1:$A$2336,'Medical Examinations'!$E$1:$E$2336,0) -> No | F23: =_xlfn.XLOOKUP(A23,'Medical Examinations'!$A$1:$A$2336,'Medical Examinations'!$F$1:$F$2336,0) -> No | G23: =_xlfn.XLOOKUP(A23,'Medical Examinations'!$A$1:$A$2336,'Medical Examinations'!$G$1:$G$2336,0) -> No | H23: =_xlfn.XLOOKUP(A23,'Medical Examinations'!$A$1:$A$2336,'Medical Examinations'!$H$1:$H$2336,0) -> 2 | I23: =_xlfn.XLOOKUP(A23,'Medical Examinations'!$A$1:$A$2336,'Medical Examinations'!$I$1:$I$2336,0) -> Yes | J23: =_xlfn.XLOOKUP(A23,'Medical Examinations'!A23:A2366,'Medical Examinations'!C23:C2366,0) -> Obese | K23: =_xlfn.XLOOKUP(A23,'Medical Examinations'!$A$1:$A$2344,'Medical Examinations'!$D$1:$D$2344,0) -> 6.22 | L23: =_xlfn.XLOOKUP(A23,'Hospitalisation Details'!$A$1:$A$2344,'Hospitalisation Details'!$E$1:$E$2344,0) -> 4-Oct-1959 | M23: =_xlfn.XLOOKUP(A23,'Hospitalisation Details'!$A$1:$A$2344,'Hospitalisation Details'!$I$1:$I$2344,0) -> 47305.31 | N23: =_xlfn.XLOOKUP(A23,'Hospitalisation Details'!$A$1:$A$2344,'Hospitalisation Details'!$J$1:$J$2344,0) -> tier - 2 | O23: =_xlfn.XLOOKUP(A23,'Hospitalisation Details'!$A$1:$A$2344,'Hospitalisation Details'!$K$1:$K$2344,0) -> tier - 1 | P23: =_xlfn.XLOOKUP(A23,'Hospitalisation Details'!$A$1:$A$2344,'Hospitalisation Details'!$L$1:$L$2344,0) -> R1011 | Q23: =_xlfn.XLOOKUP(A23,'Hospitalisation Details'!$A$1:$A$2344,'Hospitalisation Details'!$F$1:$F$2344,0) -> 63
A24: Id23 | B24: =_xlfn.XLOOKUP(A24,'Customer Names'!$A$1:$A$2336,'Customer Names'!$C$1:$C$2336,0) -> Nicole | C24: =_xlfn.XLOOKUP(A24,'Medical Examinations'!$A$1:$A$2336,'Medical Examinations'!$B$1:$B$2336,0) -> 31.3 | D24: =_xlfn.XLOOKUP(A24,'Medical Examinations'!$A$1:$A$2336,'Medical Examinations'!$D$1:$D$2336,0) -> 11.38 | E24: =_xlfn.XLOOKUP(A24,'Medical Examinations'!$A$1:$A$2336,'Medical Examinations'!$E$1:$E$2336,0) -> No | F24: =_xlfn.XLOOKUP(A24,'Medical Examinations'!$A$1:$A$2336,'Medical Examinations'!$F$1:$F$2336,0) -> No | G24: =_xlfn.XLOOKUP(A24,'Medical Examinations'!$A$1:$A$2336,'Medical Examinations'!$G$1:$G$2336,0) -> No | H24: =_xlfn.XLOOKUP(A24,'Medical Examinations'!$A$1:$A$2336,'Medical Examinations'!$H$1:$H$2336,0) -> 3 | I24: =_xlfn.XLOOKUP(A24,'Medical Examinations'!$A$1:$A$2336,'Medical Examinations'!$I$1:$I$2336,0) -> Yes | J24: =_xlfn.XLOOKUP(A24,'Medical Examinations'!A24:A2367,'Medical Examinations'!C24:C2367,0) -> Obese | K24: =_xlfn.XLOOKUP(A24,'Medical Examinations'!$A$1:$A$2344,'Medical Examinations'!$D$1:$D$2344,0) -> 11.38 | L24: =_xlfn.XLOOKUP(A24,'Hospitalisation Details'!$A$1:$A$2344,'Hospitalisation Details'!$E$1:$E$2344,0) -> 3-Sep-1958 | M24: =_xlfn.XLOOKUP(A24,'Hospitalisation Details'!$A$1:$A$2344,'Hospitalisation Details'!$I$1:$I$2344,0) -> 47291.06 | N24: =_xlfn.XLOOKUP(A24,'Hospitalisation Details'!$A$1:$A$2344,'Hospitalisation Details'!$J$1:$J$2344,0) -> tier - 2 | O24: =_xlfn.XLOOKUP(A24,'Hospitalisation Details'!$A$1:$A$2344,'Hospitalisation Details'!$K$1:$K$2344,0) -> tier - 1 | P24: =_xlfn.XLOOKUP(A24,'Hospitalisation Details'!$A$1:$A$2344,'Hospitalisation Details'!$L$1:$L$2344,0) -> R1011 | Q24: =_xlfn.XLOOKUP(A24,'Hospitalisation Details'!$A$1:$A$2344,'Hospitalisation Details'!$F$1:$F$2344,0) -> 64
A25: Id24 | B25: =_xlfn.XLOOKUP(A25,'Customer Names'!$A$1:$A$2336,'Customer Names'!$C$1:$C$2336,0) -> Eric A | C25: =_xlfn.XLOOKUP(A25,'Medical Examinations'!$A$1:$A$2336,'Medical Examinations'!$B$1:$B$2336,0) -> 41.8 | D25: =_xlfn.XLOOKUP(A25,'Medical Examinations'!$A$1:$A$2336,'Medical Examinations'!$D$1:$D$2336,0) -> 7.89 | E25: =_xlfn.XLOOKUP(A25,'Medical Examinations'!$A$1:$A$2336,'Medical Examinations'!$E$1:$E$2336,0) -> No | F25: =_xlfn.XLOOKUP(A25,'Medical Examinations'!$A$1:$A$2336,'Medical Examinations'!$F$1:$F$2336,0) -> No | G25: =_xlfn.XLOOKUP(A25,'Medical Examinations'!$A$1:$A$2336,'Medical Examinations'!$G$1:$G$2336,0) -> No | H25: =_xlfn.XLOOKUP(A25,'Medical Examinations'!$A$1:$A$2336,'Medical Examinations'!$H$1:$H$2336,0) -> 2 | I25: =_xlfn.XLOOKUP(A25,'Medical Examinations'!$A$1:$A$2336,'Medical Examinations'!$I$1:$I$2336,0) -> Yes | J25: =_xlfn.XLOOKUP(A25,'Medical Examinations'!A25:A2368,'Medical Examinations'!C25:C2368,0) -> Obese | K25: =_xlfn.XLOOKUP(A25,'Medical Examinations'!$A$1:$A$2344,'Medical Examinations'!$D$1:$D$2344,0) -> 7.89 | L25: =_xlfn.XLOOKUP(A25,'Hospitalisation Details'!$A$1:$A$2344,'Hospitalisation Details'!$E$1:$E$2344,0) -> 28-Dec-1970 | M25: =_xlfn.XLOOKUP(A25,'Hospitalisation Details'!$A$1:$A$2344,'Hospitalisation Details'!$I$1:$I$2344,0) -> 47269.85 | N25: =_xlfn.XLOOKUP(A25,'Hospitalisation Details'!$A$1:$A$2344,'Hospitalisation Details'!$J$1:$J$2344,0) -> tier - 1 | O25: =_xlfn.XLOOKUP(A25,'Hospitalisation Details'!$A$1:$A$2344,'Hospitalisation Details'!$K$1:$K$2344,0) -> tier - 2 | P25: =_xlfn.XLOOKUP(A25,'Hospitalisation Details'!$A$1:$A$2344,'Hospitalisation Details'!$L$1:$L$2344,0) -> R1013 | Q25: =_xlfn.XLOOKUP(A25,'Hospitalisation Details'!$A$1:$A$2344,'Hospitalisation Details'!$F$1:$F$2344,0) -> 52
A26: Id25 | B26: =_xlfn.XLOOKUP(A26,'Customer Names'!$A$1:$A$2336,'Customer Names'!$C$1:$C$2336,0) -> Emiliano I | C26: =_xlfn.XLOOKUP(A26,'Medical Examinations'!$A$1:$A$2336,'Medical Examinations'!$B$1:$B$2336,0) -> 35.09 | D26: =_xlfn.XLOOKUP(A26,'Medical Examinations'!$A$1:$A$2336,'Medical Examinations'!$D$1:$D$2336,0) -> 4.38 | E26: =_xlfn.XLOOKUP(A26,'Medical Examinations'!$A$1:$A$2336,'Medical Examinations'!$E$1:$E$2336,0) -> No | F26: =_xlfn.XLOOKUP(A26,'Medical Examinations'!$A$1:$A$2336,'Medical Examinations'!$F$1:$F$2336,0) -> No | G26: =_xlfn.XLOOKUP(A26,'Medical Examinations'!$A$1:$A$2336,'Medical Examinations'!$G$1:$G$2336,0) -> No | H26: =_xlfn.XLOOKUP(A26,'Medical Examinations'!$A$1:$A$2336,'Medical Examinations'!$H$1:$H$2336,0) -> 2 | I26: =_xlfn.XLOOKUP(A26,'Medical Examinations'!$A$1:$A$2336,'Medical Examinations'!$I$1:$I$2336,0) -> Yes | J26: =_xlfn.XLOOKUP(A26,'Medical Examinations'!A26:A2369,'Medical Examinations'!C26:C2369,0) -> Obese | K26: =_xlfn.XLOOKUP(A26,'Medical Examinations'!$A$1:$A$2344,'Medical Examinations'!$D$1:$D$2344,0) -> 4.38 | L26: =_xlfn.XLOOKUP(A26,'Hospitalisation Details'!$A$1:$A$2344,'Hospitalisation Details'!$E$1:$E$2344,0) -> 14-Jul-1959 | M26: =_xlfn.XLOOKUP(A26,'Hospitalisation Details'!$A$1:$A$2344,'Hospitalisation Details'!$I$1:$I$2344,0) -> 47055.53 | N26: =_xlfn.XLOOKUP(A26,'Hospitalisation Details'!$A$1:$A$2344,'Hospitalisation Details'!$J$1:$J$2344,0) -> tier - 2 | O26: =_xlfn.XLOOKUP(A26,'Hospitalisation Details'!$A$1:$A$2344,'Hospitalisation Details'!$K$1:$K$2344,0) -> tier - 1 | P26: =_xlfn.XLOOKUP(A26,'Hospitalisation Details'!$A$1:$A$2344,'Hospitalisation Details'!$L$1:$L$2344,0) -> R1013 | Q26: =_xlfn.XLOOKUP(A26,'Hospitalisation Details'!$A$1:$A$2344,'Hospitalisation Details'!$F$1:$F$2344,0) -> 63
A27: Id26 | B27: =_xlfn.XLOOKUP(A27,'Customer Names'!$A$1:$A$2336,'Customer Names'!$C$1:$C$2336,0) -> Adam | C27: =_xlfn.XLOOKUP(A27,'Medical Examinations'!$A$1:$A$2336,'Medical Examinations'!$B$1:$B$2336,0) -> 33.88 | D27: =_xlfn.XLOOKUP(A27,'Medical Examinations'!$A$1:$A$2336,'Medical Examinations'!$D$1:$D$2336,0) -> 7.01 | E27: =_xlfn.XLOOKUP(A27,'Medical Examinations'!$A$1:$A$2336,'Medical Examinations'!$E$1:$E$2336,0) -> No | F27: =_xlfn.XLOOKUP(A27,'Medical Examinations'!$A$1:$A$2336,'Medical Examinations'!$F$1:$F$2336,0) -> No | G27: =_xlfn.XLOOKUP(A27,'Medical Examinations'!$A$1:$A$2336,'Medical Examinations'!$G$1:$G$2336,0) -> No | H27: =_xlfn.XLOOKUP(A27,'Medical Examinations'!$A$1:$A$2336,'Medical Examinations'!$H$1:$H$2336,0) -> 3 | I27: =_xlfn.XLOOKUP(A27,'Medical Examinations'!$A$1:$A$2336,'Medical Examinations'!$I$1:$I$2336,0) -> Yes | J27: =_xlfn.XLOOKUP(A27,'Medical Examinations'!A27:A2370,'Medical Examinations'!C27:C2370,0) -> Obese | K27: =_xlfn.XLOOKUP(A27,'Medical Examinations'!$A$1:$A$2344,'Medical Examinations'!$D$1:$D$2344,0) -> 7.01 | L27: =_xlfn.XLOOKUP(A27,'Hospitalisation Details'!$A$1:$A$2344,'Hospitalisation Details'!$E$1:$E$2344,0) -> 15-Sep-1958 | M27: =_xlfn.XLOOKUP(A27,'Hospitalisation Details'!$A$1:$A$2344,'Hospitalisation Details'!$I$1:$I$2344,0) -> 46889.26 | N27: =_xlfn.XLOOKUP(A27,'Hospitalisation Details'!$A$1:$A$2344,'Hospitalisation Details'!$J$1:$J$2344,0) -> tier - 2 | O27: =_xlfn.XLOOKUP(A27,'Hospitalisation Details'!$A$1:$A$2344,'Hospitalisation Details'!$K$1:$K$2344,0) -> tier - 3 | P27: =_xlfn.XLOOKUP(A27,'Hospitalisation Details'!$A$1:$A$2344,'Hospitalisation Details'!$L$1:$L$2344,0) -> R1013 | Q27: =_xlfn.XLOOKUP(A27,'Hospitalisation Details'!$A$1:$A$2344,'Hospitalisation Details'!$F$1:$F$2344,0) -> 64
A28: Id27 | B28: =_xlfn.XLOOKUP(A28,'Customer Names'!$A$1:$A$2336,'Customer Names'!$C$1:$C$2336,0) -> Zach | C28: =_xlfn.XLOOKUP(A28,'Medical Examinations'!$A$1:$A$2336,'Medical Examinations'!$B$1:$B$2336,0) -> 30.875 | D28: =_xlfn.XLOOKUP(A28,'Medical Examinations'!$A$1:$A$2336,'Medical Examinations'!$D$1:$D$2336,0) -> 11.88 | E28: =_xlfn.XLOOKUP(A28,'Medical Examinations'!$A$1:$A$2336,'Medical Examinations'!$E$1:$E$2336,0) -> No | F28: =_xlfn.XLOOKUP(A28,'Medical Examinations'!$A$1:$A$2336,'Medical Examinations'!$F$1:$F$2336,0) -> No | G28: =_xlfn.XLOOKUP(A28,'Medical Examinations'!$A$1:$A$2336,'Medical Examinations'!$G$1:$G$2336,0) -> No | H28: =_xlfn.XLOOKUP(A28,'Medical Examinations'!$A$1:$A$2336,'Medical Examinations'!$H$1:$H$2336,0) -> 0 | I28: =_xlfn.XLOOKUP(A28,'Medical Examinations'!$A$1:$A$2336,'Medical Examinations'!$I$1:$I$2336,0) -> Yes | J28: =_xlfn.XLOOKUP(A28,'Medical Examinations'!A28:A2371,'Medical Examinations'!C28:C2371,0) -> Obese | K28: =_xlfn.XLOOKUP(A28,'Medical Examinations'!$A$1:$A$2344,'Medical Examinations'!$D$1:$D$2344,0) -> 11.88 | L28: =_xlfn.XLOOKUP(A28,'Hospitalisation Details'!$A$1:$A$2344,'Hospitalisation Details'!$E$1:$E$2344,0) -> 17-Nov-1960 | M28: =_xlfn.XLOOKUP(A28,'Hospitalisation Details'!$A$1:$A$2344,'Hospitalisation Details'!$I$1:$I$2344,0) -> 46718.16 | N28: =_xlfn.XLOOKUP(A28,'Hospitalisation Details'!$A$1:$A$2344,'Hospitalisation Details'!$J$1:$J$2344,0) -> tier - 1 | O28: =_xlfn.XLOOKUP(A28,'Hospitalisation Details'!$A$1:$A$2344,'Hospitalisation Details'!$K$1:$K$2344,0) -> tier - 1 | P28: =_xlfn.XLOOKUP(A28,'Hospitalisation Details'!$A$1:$A$2344,'Hospitalisation Details'!$L$1:$L$2344,0) -> R1012 | Q28: =_xlfn.XLOOKUP(A28,'Hospitalisation Details'!$A$1:$A$2344,'Hospitalisation Details'!$F$1:$F$2344,0) -> 62
A29: Id28 | B29: =_xlfn.XLOOKUP(A29,'Customer Names'!$A$1:$A$2336,'Customer Names'!$C$1:$C$2336,0) -> Stephanie W | C29: =_xlfn.XLOOKUP(A29,'Medical Examinations'!$A$1:$A$2336,'Medical Examinations'!$B$1:$B$2336,0) -> 36.86 | D29: =_xlfn.XLOOKUP(A29,'Medical Examinations'!$A$1:$A$2336,'Medical Examinations'!$D$1:$D$2336,0) -> 5.19 | E29: =_xlfn.XLOOKUP(A29,'Medical Examinations'!$A$1:$A$2336,'Medical Examinations'!$E$1:$E$2336,0) -> No | F29: =_xlfn.XLOOKUP(A29,'Medical Examinations'!$A$1:$A$2336,'Medical Examinations'!$F$1:$F$2336,0) -> No | G29: =_xlfn.XLOOKUP(A29,'Medical Examinations'!$A$1:$A$2336,'Medical Examinations'!$G$1:$G$2336,0) -> Yes | H29: =_xlfn.XLOOKUP(A29,'Medical Examinations'!$A$1:$A$2336,'Medical Examinations'!$H$1:$H$2336,0) -> 1 | I29: =_xlfn.XLOOKUP(A29,'Medical Examinations'!$A$1:$A$2336,'Medical Examinations'!$I$1:$I$2336,0) -> Yes | J29: =_xlfn.XLOOKUP(A29,'Medical Examinations'!A29:A2372,'Medical Examinations'!C29:C2372,0) -> Obese | K29: =_xlfn.XLOOKUP(A29,'Medical Examinations'!$A$1:$A$2344,'Medical Examinations'!$D$1:$D$2344,0) -> 5.19 | L29: =_xlfn.XLOOKUP(A29,'Hospitalisation Details'!$A$1:$A$2344,'Hospitalisation Details'!$E$1:$E$2344,0) -> 23-Jun-1969 | M29: =_xlfn.XLOOKUP(A29,'Hospitalisation Details'!$A$1:$A$2344,'Hospitalisation Details'!$I$1:$I$2344,0) -> 46661.44 | N29: =_xlfn.XLOOKUP(A29,'Hospitalisation Details'!$A$1:$A$2344,'Hospitalisation Details'!$J$1:$J$2344,0) -> tier - 1 | O29: =_xlfn.XLOOKUP(A29,'Hospitalisation Details'!$A$1:$A$2344,'Hospitalisation Details'!$K$1:$K$2344,0) -> tier - 3 | P29: =_xlfn.XLOOKUP(A29,'Hospitalisation Details'!$A$1:$A$2344,'Hospitalisation Details'!$L$1:$L$2344,0) -> R1012 | Q29: =_xlfn.XLOOKUP(A29,'Hospitalisation Details'!$A$1:$A$2344,'Hospitalisation Details'!$F$1:$F$2344,0) -> 53
A30: Id29 | B30: =_xlfn.XLOOKUP(A30,'Customer Names'!$A$1:$A$2336,'Customer Names'!$C$1:$C$2336,0) -> Stephen | C30: =_xlfn.XLOOKUP(A30,'Medical Examinations'!$A$1:$A$2336,'Medical Examinations'!$B$1:$B$2336,0) -> 35.86 | D30: =_xlfn.XLOOKUP(A30,'Medical Examinations'!$A$1:$A$2336,'Medical Examinations'!$D$1:$D$2336,0) -> 6.74 | E30: =_xlfn.XLOOKUP(A30,'Medical Examinations'!$A$1:$A$2336,'Medical Examinations'!$E$1:$E$2336,0) -> No | F30: =_xlfn.XLOOKUP(A30,'Medical Examinations'!$A$1:$A$2336,'Medical Examinations'!$F$1:$F$2336,0) -> No | G30: =_xlfn.XLOOKUP(A30,'Medical Examinations'!$A$1:$A$2336,'Medical Examinations'!$G$1:$G$2336,0) -> No | H30: =_xlfn.XLOOKUP(A30,'Medical Examinations'!$A$1:$A$2336,'Medical Examinations'!$H$1:$H$2336,0) -> 2 | I30: =_xlfn.XLOOKUP(A30,'Medical Examinations'!$A$1:$A$2336,'Medical Examinations'!$I$1:$I$2336,0) -> Yes | J30: =_xlfn.XLOOKUP(A30,'Medical Examinations'!A30:A2373,'Medical Examinations'!C30:C2373,0) -> Obese | K30: =_xlfn.XLOOKUP(A30,'Medical Examinations'!$A$1:$A$2344,'Medical Examinations'!$D$1:$D$2344,0) -> 6.74 | L30: =_xlfn.XLOOKUP(A30,'Hospitalisation Details'!$A$1:$A$2344,'Hospitalisation Details'!$E$1:$E$2344,0) -> 8-Aug-1961 | M30: =_xlfn.XLOOKUP(A30,'Hospitalisation Details'!$A$1:$A$2344,'Hospitalisation Details'!$I$1:$I$2344,0) -> 46599.11 | N30: =_xlfn.XLOOKUP(A30,'Hospitalisation Details'!$A$1:$A$2344,'Hospitalisation Details'!$J$1:$J$2344,0) -> tier - 1 | O30: =_xlfn.XLOOKUP(A30,'Hospitalisation Details'!$A$1:$A$2344,'Hospitalisation Details'!$K$1:$K$2344,0) -> tier - 1 | P30: =_xlfn.XLOOKUP(A30,'Hospitalisation Details'!$A$1:$A$2344,'Hospitalisation Details'!$L$1:$L$2344,0) -> R1013 | Q30: =_xlfn.XLOOKUP(A30,'Hospitalisation Details'!$A$1:$A$2344,'Hospitalisation Details'!$F$1:$F$2344,0) -> 61
A31: Id30 | B31: =_xlfn.XLOOKUP(A31,'Customer Names'!$A$1:$A$2336,'Customer Names'!$C$1:$C$2336,0) -> Natalie | C31: =_xlfn.XLOOKUP(A31,'Medical Examinations'!$A$1:$A$2336,'Medical Examinations'!$B$1:$B$2336,0) -> 37.05 | D31: =_xlfn.XLOOKUP(A31,'Medical Examinations'!$A$1:$A$2336,'Medical Examinations'!$D$1:$D$2336,0) -> 8.44 | E31: =_xlfn.XLOOKUP(A31,'Medical Examinations'!$A$1:$A$2336,'Medical Examinations'!$E$1:$E$2336,0) -> No | F31: =_xlfn.XLOOKUP(A31,'Medical Examinations'!$A$1:$A$2336,'Medical Examinations'!$F$1:$F$2336,0) -> No | G31: =_xlfn.XLOOKUP(A31,'Medical Examinations'!$A$1:$A$2336,'Medical Examinations'!$G$1:$G$2336,0) -> No | H31: =_xlfn.XLOOKUP(A31,'Medical Examinations'!$A$1:$A$2336,'Medical Examinations'!$H$1:$H$2336,0) -> 0 | I31: =_xlfn.XLOOKUP(A31,'Medical Examinations'!$A$1:$A$2336,'Medical Examinations'!$I$1:$I$2336,0) -> Yes | J31: =_xlfn.XLOOKUP(A31,'Medical Examinations'!A31:A2374,'Medical Examinations'!C31:C2374,0) -> Obese | K31: =_xlfn.XLOOKUP(A31,'Medical Examinations'!$A$1:$A$2344,'Medical Examinations'!$D$1:$D$2344,0) -> 8.44 | L31: =_xlfn.XLOOKUP(A31,'Hospitalisation Details'!$A$1:$A$2344,'Hospitalisation Details'!$E$1:$E$2344,0) -> 6-Dec-1971 | M31: =_xlfn.XLOOKUP(A31,'Hospitalisation Details'!$A$1:$A$2344,'Hospitalisation Details'!$I$1:$I$2344,0) -> 46255.11 | N31: =_xlfn.XLOOKUP(A31,'Hospitalisation Details'!$A$1:$A$2344,'Hospitalisation Details'!$J$1:$J$2344,0) -> tier - 1 | O31: =_xlfn.XLOOKUP(A31,'Hospitalisation Details'!$A$1:$A$2344,'Hospitalisation Details'!$K$1:$K$2344,0) -> tier - 3 | P31: =_xlfn.XLOOKUP(A31,'Hospitalisation Details'!$A$1:$A$2344,'Hospitalisation Details'!$L$1:$L$2344,0) -> R1024 | Q31: =_xlfn.XLOOKUP(A31,'Hospitalisation Details'!$A$1:$A$2344,'Hospitalisation Details'!$F$1:$F$2344,0) -> 51
